<?xml version="1.0" encoding="utf-8"?>
<!-- This URDF was automatically created by SolidWorks to URDF Exporter! Originally created by Stephen Brawner (brawner@gmail.com) 
     Commit Version: 1.6.0-4-g7f85cfe  Build Version: 1.6.7995.38578
     For more information, please see http://wiki.ros.org/sw_urdf_exporter -->
<robot xmlns:xacro="http://www.ros.org/wiki/xacro"
  name="ZavaQuin">
  <link
    name="base_link">
    <inertial>
      <origin
        xyz="-0.000260364695511453 0.00187283839491649 0.044474815477357"
        rpy="0 0 0" />
      <mass
        value="4.4576232231282" />
      <inertia
        ixx="0.0442662275832894"
        ixy="-2.15146521458688E-05"
        ixz="-2.28143383757141E-07"
        iyy="0.029789050471583"
        iyz="-3.51221173367627E-05"
        izz="0.07249409145326" />
    </inertial>
    <visual>
      <origin
        xyz="0 0 0"
        rpy="0 0 0" />
      <geometry>
        <mesh
          filename="package://ZavaQuin/meshes/base_link.STL" />
      </geometry>
      <material
        name="">
        <color
          rgba="0.749019607843137 0.749019607843137 0.749019607843137 1" />
      </material>
    </visual>
    <collision>
      <origin
        xyz="0 0 0"
        rpy="0 0 0" />
      <geometry>
        <mesh
          filename="package://ZavaQuin/meshes/base_link.STL" />
      </geometry>
    </collision>
  </link>
  <link
    name="wheel_left_link">
    <inertial>
      <origin
        xyz="0 0 -0.00015430903826355"
        rpy="0 0 0" />
      <mass
        value="0.190866532892921" />
      <inertia
        ixx="0.000153745462220156"
        ixy="-1.87226503814821E-21"
        ixz="-1.25042522522111E-19"
        iyy="0.000153745462220156"
        iyz="-2.35718360863885E-21"
        izz="0.000277717161348545" />
    </inertial>
    <visual>
      <origin
        xyz="0 0 0"
        rpy="0 0 0" />
      <geometry>
        <mesh
          filename="package://ZavaQuin/meshes/wheel_left_link.STL" />
      </geometry>
      <material
        name="">
        <color
          rgba="0.792156862745098 0.819607843137255 0.933333333333333 1" />
      </material>
    </visual>
    <collision>
      <origin
        xyz="0 0 0"
        rpy="0 0 0" />
      <geometry>
        <mesh
          filename="package://ZavaQuin/meshes/wheel_left_link.STL" />
      </geometry>
    </collision>
  </link>
  <joint
    name="wheel_left_joint"
    type="continuous">
    <origin
      xyz="0.13319 0.18268 0.04"
      rpy="-1.5708 0 -1.5708" />
    <parent
      link="base_link" />
    <child
      link="wheel_left_link" />
    <axis
      xyz="0 0 1" />
  </joint>
  <link
    name="wheel_right_link">
    <inertial>
      <origin
        xyz="0 0 0.00015430903826355"
        rpy="0 0 0" />
      <mass
        value="0.190866532892921" />
      <inertia
        ixx="0.000153745462220156"
        ixy="-1.4319617412795E-21"
        ixz="-1.24760368762001E-19"
        iyy="0.000153745462220156"
        iyz="-2.45020547725608E-21"
        izz="0.000277717161348545" />
    </inertial>
    <visual>
      <origin
        xyz="0 0 0"
        rpy="0 0 0" />
      <geometry>
        <mesh
          filename="package://ZavaQuin/meshes/wheel_right_link.STL" />
      </geometry>
      <material
        name="">
        <color
          rgba="0.792156862745098 0.819607843137255 0.933333333333333 1" />
      </material>
    </visual>
    <collision>
      <origin
        xyz="0 0 0"
        rpy="0 0 0" />
      <geometry>
        <mesh
          filename="package://ZavaQuin/meshes/wheel_right_link.STL" />
      </geometry>
    </collision>
  </link>
  <joint
    name="wheel_right_joint"
    type="continuous">
    <origin
      xyz="-0.13681 0.18268 0.04"
      rpy="-1.5708 0 -1.5708" />
    <parent
      link="base_link" />
    <child
      link="wheel_right_link" />
    <axis
      xyz="0 0 1" />
  </joint>
  <link
    name="caster_wheel_link">
    <inertial>
      <origin
        xyz="-2.77555756156289E-17 -2.77555756156289E-17 0"
        rpy="0 0 0" />
      <mass
        value="0.113097335529233" />
      <inertia
        ixx="4.07150407905237E-05"
        ixy="0"
        ixz="1.94368867832977E-37"
        iyy="4.07150407905237E-05"
        iyz="1.24653860953172E-21"
        izz="4.07150407905237E-05" />
    </inertial>
    <visual>
      <origin
        xyz="0 0 0"
        rpy="0 0 0" />
      <geometry>
        <mesh
          filename="package://ZavaQuin/meshes/caster_wheel_link.STL" />
      </geometry>
      <material
        name="">
        <color
          rgba="0.749019607843137 0.749019607843137 0.749019607843137 1" />
      </material>
    </visual>
    <collision>
      <origin
        xyz="0 0 0"
        rpy="0 0 0" />
      <geometry>
        <mesh
          filename="package://ZavaQuin/meshes/caster_wheel_link.STL" />
      </geometry>
    </collision>
  </link>
  <joint
    name="caster_wheel_joint"
    type="fixed">
    <origin
      xyz="-4.4845E-05 -0.16235 0.018397"
      rpy="-1.5708 0 -1.5708" />
    <parent
      link="base_link" />
    <child
      link="caster_wheel_link" />
    <axis
      xyz="0 0 0" />
    <limit
      lower="0"
      upper="0"
      effort="0"
      velocity="0" />
  </joint>
  <link
    name="camera_link">
    <inertial>
      <origin
        xyz="0.00965243593561138 1.8385720590236E-05 -0.000163427102087707"
        rpy="0 0 0" />
      <mass
        value="0.0332100658718068" />
      <inertia
        ixx="2.27127334837262E-05"
        ixy="-6.70660167244545E-09"
        ixz="1.82045654663639E-08"
        iyy="2.69592706510735E-06"
        iyz="-9.95791579616354E-12"
        izz="2.24858404357307E-05" />
    </inertial>
    <visual>
      <origin
        xyz="0 0 0"
        rpy="0 0 0" />
      <geometry>
        <mesh
          filename="package://ZavaQuin/meshes/camera_link.STL" />
      </geometry>
      <material
        name="">
        <color
          rgba="0.866666666666667 0.909803921568627 1 1" />
      </material>
    </visual>
    <collision>
      <origin
        xyz="0 0 0"
        rpy="0 0 0" />
      <geometry>
        <mesh
          filename="package://ZavaQuin/meshes/camera_link.STL" />
      </geometry>
    </collision>
  </link>
  <joint
    name="camera_joint"
    type="fixed">
    <origin
      xyz="0.00039991 -0.17103 0.097276"
      rpy="0 0 -1.5708" />
    <parent
      link="base_link" />
    <child
      link="camera_link" />
    <axis
      xyz="0 0 0" />
  </joint>
  <link
    name="laser_link">
    <inertial>
      <origin
        xyz="-0.000108850676728708 1.1004985988522E-05 -0.0112166143877991"
        rpy="0 0 0" />
      <mass
        value="0.0402897893770633" />
      <inertia
        ixx="7.68822376371184E-06"
        ixy="9.92757114808107E-08"
        ixz="-5.26149372846125E-08"
        iyy="7.61639192639203E-06"
        iyz="5.59904036135235E-09"
        izz="8.2844932139337E-06" />
    </inertial>
    <visual>
      <origin
        xyz="0 0 0"
        rpy="0 0 0" />
      <geometry>
        <mesh
          filename="package://ZavaQuin/meshes/laser_link.STL" />
      </geometry>
      <material
        name="">
        <color
          rgba="0.792156862745098 0.819607843137255 0.933333333333333 1" />
      </material>
    </visual>
    <collision>
      <origin
        xyz="0 0 0"
        rpy="0 0 0" />
      <geometry>
        <mesh
          filename="package://ZavaQuin/meshes/laser_link.STL" />
      </geometry>
    </collision>
  </link>
  <joint
    name="laser_joint"
    type="fixed">
    <origin
      xyz="0.0030503 0.0075651 0.1385"
      rpy="0 0 -1.5708" />
    <parent
      link="base_link" />
    <child
      link="laser_link" />
    <axis
      xyz="0 0 0" />
  </joint>
  <link
    name="imu_link">
    <inertial>
      <origin
        xyz="-0.0300366459686936 0.0155404733834772 0.00325865052446311"
        rpy="0 0 0" />
      <mass
        value="0.0173828871756339" />
      <inertia
        ixx="4.34865051839205E-06"
        ixy="4.63050620378652E-09"
        ixz="1.8818930673377E-09"
        iyy="3.13206596794726E-06"
        iyz="1.06427999775274E-09"
        izz="7.11315681917902E-06" />
    </inertial>
    <visual>
      <origin
        xyz="0 0 0"
        rpy="0 0 0" />
      <geometry>
        <mesh
          filename="package://ZavaQuin/meshes/imu_link.STL" />
      </geometry>
      <material
        name="">
        <color
          rgba="0.827450980392157 0.83921568627451 0.827450980392157 1" />
      </material>
    </visual>
    <collision>
      <origin
        xyz="0 0 0"
        rpy="0 0 0" />
      <geometry>
        <mesh
          filename="package://ZavaQuin/meshes/imu_link.STL" />
      </geometry>
    </collision>
  </link>
  <joint
    name="imu_joint"
    type="fixed">
    <origin
      xyz="-0.0390281436839592 0.0549871759093349 0.010774999999999"
      rpy="0 0 -1.5707963267949" />
    <parent
      link="base_link" />
    <child
      link="imu_link" />
    <axis
      xyz="0 0 0" />
  </joint>
  
  
  <!-- Configuration Wheels -->
  <gazebo reference="wheel_left_link">
    <mu1>10000.0</mu1>
    <mu2>10000.0</mu2>
    <kp>3000000.0</kp>
    <kd>90.0</kd>
    <minDepth>0.001</minDepth>
    <maxVel>0.1</maxVel>
    <fdir1>1 0 0</fdir1>
    <material>Gazebo/FlatBlack</material>
  </gazebo>

  <gazebo reference="wheel_right_link">
    <mu1>10000.0</mu1>
    <mu2>10000.0</mu2>
    <kp>3000000.0</kp>
    <kd>90.0</kd>
    <minDepth>0.001</minDepth>
    <maxVel>0.1</maxVel>
    <fdir1>1 0 0</fdir1>
    <material>Gazebo/FlatBlack</material>
  </gazebo>
  
  <gazebo reference="caster_wheel_link">
    <mu1>0.1</mu1>
    <mu2>0.1</mu2>
    <material>Gazebo/FlatBlack</material>
  </gazebo>
  
  
  <!-- Plugin -->
  <gazebo>
    <!-- Plugin control ruedas diferenciales -->
    <plugin name="wheel_drive_controller" filename="libgazebo_ros_diff_drive.so">
      <ros>
        <namespace></namespace>
        <remapping>cmd_vel:=cmd_vel</remapping>
        <remapping>odom:=odom</remapping>
      </ros>
      <update_rate>1</update_rate>
      <left_joint>left_joint</left_joint>
      <right_joint>right_joint</right_joint>
      <wheel_separation>0.229</wheel_separation>
      <wheel_diameter>0.072</wheel_diameter>
      <max_wheel_torque>10</max_wheel_torque>
      <max_wheel_acceleration>1.0</max_wheel_acceleration>
      <publish_odom>true</publish_odom>
      <publish_odom_tf>true</publish_odom_tf>
      <publish_wheel_tf>true</publish_wheel_tf>
      <odometry_frame>odom</odometry_frame>
      <robot_base_frame>base_footprint</robot_base_frame>
    </plugin>
  </gazebo>
</robot>
