<?xml version="1.0" encoding="utf-8"?>
<!-- This URDF was automatically created by SolidWorks to URDF Exporter! Originally created by Stephen Brawner (brawner@gmail.com) 
     Commit Version: 1.6.0-4-g7f85cfe  Build Version: 1.6.7995.38578
     For more information, please see http://wiki.ros.org/sw_urdf_exporter -->
<robot xmlns:xacro="http://www.ros.org/wiki/xacro" name="zavaquin">
  <xacro:arg name="use_ros2_control" default="true"/>
  <xacro:arg name="sim_mode" default="false"/>

  <link name="base_footprint"/>

  <joint name="base_footprint_to_base_link" type="fixed">
    <origin xyz="0 0 0.016" rpy="0 0 0" />
    <parent link="base_footprint" />
    <child link="base_link" />
  </joint>

  <link name="base_link">
    <inertial>
      <origin xyz="-0.000260364695511453 0.00187283839491649 0.044474815477357" rpy="0 0 0" />
      <mass value="4.4576232231282" />
      <inertia
        ixx="0.0442662275832894"
        ixy="-2.15146521458688E-05"
        ixz="-2.28143383757141E-07"
        iyy="0.029789050471583"
        iyz="-3.51221173367627E-05"
        izz="0.07249409145326" />
    </inertial>
    <visual>
      <origin xyz="0 0 0" rpy="0 0 0" />
      <geometry>
        <mesh filename="package://zavaquin_description/meshes/base_link.STL" />
      </geometry>
      <material name="">
        <color rgba="0.749019607843137 0.749019607843137 0.749019607843137 1" />
      </material>
    </visual>
    <collision>
      <origin xyz="0 0 0" rpy="0 0 0" />
      <geometry>
        <mesh filename="package://zavaquin_description/meshes/base_link.STL" />
      </geometry>
    </collision>
  </link>

  <link name="wheel_left_link">
    <inertial>
      <origin xyz="0 0 -0.00015430903826355" rpy="0 0 0" />
      <mass value="0.190866532892921" />
      <inertia
        ixx="0.000153745462220156"
        ixy="-1.87226503814821E-21"
        ixz="-1.25042522522111E-19"
        iyy="0.000153745462220156"
        iyz="-2.35718360863885E-21"
        izz="0.000277717161348545" />
    </inertial>
    <visual>
      <origin xyz="0 0 0" rpy="0 0 0" />
      <geometry>
        <mesh filename="package://zavaquin_description/meshes/wheel_left_link.STL" />
      </geometry>
      <material name="">
        <color rgba="0.792156862745098 0.819607843137255 0.933333333333333 1" />
      </material>
    </visual>
    <collision>
      <origin xyz="0 0 0" rpy="0 0 0" />
      <geometry>
        <mesh filename="package://zavaquin_description/meshes/wheel_left_link.STL" />
      </geometry>
    </collision>
  </link>

  <joint name="wheel_left_joint" type="continuous">
    <origin xyz="0.13319 0.18268 0.04" rpy="-1.5708 0 -1.5708" />
    <parent link="base_link" />
    <child link="wheel_left_link" />
    <axis xyz="0 0 1" />
  </joint>

  <link name="wheel_right_link">
    <inertial>
      <origin xyz="0 0 0.00015430903826355" rpy="0 0 0" />
      <mass value="0.190866532892921" />
      <inertia
        ixx="0.000153745462220156"
        ixy="-1.4319617412795E-21"
        ixz="-1.24760368762001E-19"
        iyy="0.000153745462220156"
        iyz="-2.45020547725608E-21"
        izz="0.000277717161348545" />
    </inertial>
    <visual>
      <origin xyz="0 0 0" rpy="0 0 0" />
      <geometry>
        <mesh filename="package://zavaquin_description/meshes/wheel_right_link.STL" />
      </geometry>
      <material name="">
        <color rgba="0.792156862745098 0.819607843137255 0.933333333333333 1" />
      </material>
    </visual>
    <collision>
      <origin xyz="0 0 0" rpy="0 0 0" />
      <geometry>
        <mesh filename="package://zavaquin_description/meshes/wheel_right_link.STL" />
      </geometry>
    </collision>
  </link>

  <joint name="wheel_right_joint" type="continuous">
    <origin xyz="-0.13681 0.18268 0.04" rpy="-1.5708 0 -1.5708" />
    <parent link="base_link" />
    <child link="wheel_right_link" />
    <axis xyz="0 0 1" />
  </joint>

  <link name="caster_wheel_link">
    <inertial>
      <origin xyz="-2.77555756156289E-17 -2.77555756156289E-17 0" rpy="0 0 0" />
      <mass value="0.113097335529233" />
      <inertia
        ixx="4.07150407905237E-05"
        ixy="0"
        ixz="1.94368867832977E-37"
        iyy="4.07150407905237E-05"
        iyz="1.24653860953172E-21"
        izz="4.07150407905237E-05" />
    </inertial>
    <visual>
      <origin xyz="0 0 0" rpy="0 0 0" />
      <geometry>
        <mesh filename="package://zavaquin_description/meshes/caster_wheel_link.STL" />
      </geometry>
      <material name="">
        <color rgba="0.749019607843137 0.749019607843137 0.749019607843137 1" />
      </material>
    </visual>
    <collision>
      <origin xyz="0 0 0" rpy="0 0 0" />
      <geometry>
        <mesh filename="package://zavaquin_description/meshes/caster_wheel_link.STL" />
      </geometry>
    </collision>
  </link>

  <joint name="caster_wheel_joint" type="fixed">
    <origin xyz="-4.4845E-05 -0.16235 0.018397" rpy="-1.5708 0 -1.5708" />
    <parent link="base_link" />
    <child link="caster_wheel_link" />
    <axis xyz="0 0 0" />
    <limit
      lower="0"
      upper="0"
      effort="0"
      velocity="0" />
  </joint>

  <!-- Configuration Wheels -->
  <gazebo reference="wheel_left_link">
    <mu1>10000.0</mu1>
    <mu2>10000.0</mu2>
    <kp>3000000.0</kp>
    <kd>90.0</kd>
    <minDepth>0.001</minDepth>
    <maxVel>0.1</maxVel>
    <fdir1>1 0 0</fdir1>
    <material>Gazebo/FlatBlack</material>
  </gazebo>

  <gazebo reference="wheel_right_link">
    <mu1>10000.0</mu1>
    <mu2>10000.0</mu2>
    <kp>3000000.0</kp>
    <kd>90.0</kd>
    <minDepth>0.001</minDepth>
    <maxVel>0.1</maxVel>
    <fdir1>1 0 0</fdir1>
    <material>Gazebo/FlatBlack</material>
  </gazebo>
  
  <gazebo reference="caster_wheel_link">
    <mu1>0.1</mu1>
    <mu2>0.1</mu2>
    <material>Gazebo/FlatBlack</material>
  </gazebo>
  
  <xacro:if value="$(arg use_ros2_control)">
      <xacro:include filename="ros2_control.xacro"/>
  </xacro:if>

  <xacro:unless value="$(arg use_ros2_control)">
      <xacro:include filename="gazebo_control.xacro"/>
  </xacro:unless>

  <xacro:include filename="camera.xacro"/>
  <xacro:include filename="imu.xacro"/>
  <xacro:include filename="lidar.xacro"/> 
  
</robot>
