<?xml version="1.0" encoding="utf-8"?>
<!-- This URDF was automatically created by SolidWorks to URDF Exporter! Originally created by Stephen Brawner (brawner@gmail.com) 
     Commit Version: 1.6.0-4-g7f85cfe  Build Version: 1.6.7995.38578
     For more information, please see http://wiki.ros.org/sw_urdf_exporter -->
<robot xmlns:xacro="http://www.ros.org/wiki/xacro" name="zavaquin">

  <material name="dark">
    <color rgba="0.01960784313 0.01960784313 0.01960784313 1.0" />
  </material>

  <material name="red">
    <color rgba="0.89019607843 0.14509803921 0.12156862745 1.0" />
  </material>

  <link name="base_footprint"/>

  <joint name="base_footprint_to_base_link" type="fixed">
    <origin xyz="0 0 0.016" rpy="0 0 0" />
    <parent link="base_footprint" />
    <child link="base_link" />
  </joint>

  <link name="base_link">
    <inertial>
      <origin xyz="-0.0021958 -0.00035059 0.044357" rpy="0 0 0" />
      <mass value="4.4576232231282" />
      <inertia ixx="0.029793" ixy="2.1519E-05" ixz="3.5124E-05" iyy="0.044269" iyz="-2.2708E-07" izz="0.072501" />
    </inertial>
    <visual>
      <origin xyz="0 0 0" rpy="0 0 0" />
      <geometry>
        <mesh filename="package://zavaquin_description/meshes/base_link.STL" />
      </geometry>
      <material name="red" />
    </visual>
    <collision>
      <origin xyz="0 0 0" rpy="0 0 0" />
      <geometry>
        <mesh filename="package://zavaquin_description/meshes/base_link.STL" />
      </geometry>
    </collision>
  </link>

  <link name="wheel_left_link">
    <inertial>
      <origin xyz="2.7756E-17 0 -0.015154" rpy="0 0 0" />
      <mass value="0.190866532892921" />
      <inertia ixx="0.00015375" ixy="-1.8747E-21" ixz="-1.2515E-19" iyy="0.00015375" iyz="-2.3486E-21" izz="0.00027772" />
    </inertial>
    <visual>
      <origin xyz="0 0 0" rpy="0 0 0" />
      <geometry>
        <mesh filename="package://zavaquin_description/meshes/wheel_left_link.STL" />
      </geometry>
      <material name="dark" />
    </visual>
    <collision>
      <origin xyz="0 0 0" rpy="0 0 0" />
      <geometry>
        <mesh filename="package://zavaquin_description/meshes/wheel_left_link.STL" />
      </geometry>
    </collision>
  </link>

  <joint name="wheel_left_joint" type="continuous">
    <origin xyz="-0.18268 0.14819 0.04" rpy="-1.5708 0 0" />
    <parent link="base_link" />
    <child link="wheel_left_link" />
    <axis xyz="0 0 1" />
  </joint>

  <link name="wheel_right_link">
    <inertial>
      <origin xyz="-2.7756E-17 0 0.015154" rpy="0 0 0" />
      <mass value="0.190866532892921" />
      <inertia ixx="0.00015375" ixy="-1.4203E-21" ixz="-1.2479E-19" iyy="0.00015375" iyz="-2.4414E-21" izz="0.00027772" />
    </inertial>
    <visual>
      <origin xyz="0 0 0" rpy="0 0 0" />
      <geometry>
        <mesh filename="package://zavaquin_description/meshes/wheel_right_link.STL" />
      </geometry>
      <material name="dark" />
    </visual>
    <collision>
      <origin xyz="0 0 0" rpy="0 0 0" />
      <geometry>
        <mesh filename="package://zavaquin_description/meshes/wheel_right_link.STL" />
      </geometry>
    </collision>
  </link>

  <joint name="wheel_right_joint" type="continuous">
    <origin xyz="-0.18268 -0.15181 0.04" rpy="-1.5708 0 0" />
    <parent link="base_link" />
    <child link="wheel_right_link" />
    <axis xyz="0 0 1" />
  </joint>

  <link name="caster_wheel_link">
    <inertial>
      <origin xyz="-2.7756E-17 0 2.7756E-17" rpy="0 0 0" />
      <mass value="0.113097335529233" />
      <inertia ixx="4.0715E-05" ixy="1.9437E-37" ixz="0" iyy="4.0715E-05" iyz="-1.2465E-21" izz="4.0715E-05" />
    </inertial>
    <visual>
      <origin xyz="0 0 0" rpy="0 0 0" />
      <geometry>
        <mesh filename="package://zavaquin_description/meshes/caster_wheel_link.STL" />
      </geometry>
      <material name="dark" />
    </visual>
    <collision>
      <origin xyz="0 0 0" rpy="0 0 0" />
      <geometry>
        <mesh filename="package://zavaquin_description/meshes/caster_wheel_link.STL" />
      </geometry>
    </collision>
  </link>

  <joint name="caster_wheel_joint" type="fixed">
    <origin xyz="0.16235 -4.4845E-05 0.018397" rpy="0 0 0" />
    <parent link="base_link" />
    <child link="caster_wheel_link" />
    <axis xyz="0 0 0" />
    <!-- <limit lower="0" upper="0" effort="0" velocity="0" /> -->
    <dynamics damping="0.01" friction="0.0"/>
  </joint>

  <!-- Configuration Wheels -->
  <gazebo reference="wheel_left_link">
    <mu1>10000.0</mu1>
    <mu2>10000.0</mu2>
    <kp>3000000.0</kp>
    <kd>90.0</kd>
    <minDepth>0.001</minDepth>
    <maxVel>0.1</maxVel>
    <fdir1>1 0 0</fdir1>
  </gazebo>

  <gazebo reference="wheel_right_link">
    <mu1>10000.0</mu1>
    <mu2>10000.0</mu2>
    <kp>3000000.0</kp>
    <kd>90.0</kd>
    <minDepth>0.001</minDepth>
    <maxVel>0.1</maxVel>
    <fdir1>1 0 0</fdir1>
  </gazebo>

  <gazebo reference="caster_wheel_link">
    <mu1>0.1</mu1>
    <mu2>0.1</mu2>
  </gazebo>

  <gazebo>
    <plugin name="zavaquin_joint_state" filename="libgazebo_ros_joint_state_publisher.so">
      <ros>
        <remapping>~/out:=joint_states</remapping>
        <remapping>/tf:=tf</remapping>
      </ros>
      <update_rate>30</update_rate>
      <joint_name>wheel_right_joint</joint_name>
      <joint_name>wheel_left_joint</joint_name>
      <joint_name>caster_wheel_joint</joint_name>
    </plugin>

    <plugin name="zavaquin_diff_drive" filename="libgazebo_ros_diff_drive.so">
      <ros>
        <namespace></namespace>
        <remapping>cmd_vel:=cmd_vel</remapping>
        <remapping>odom:=odom</remapping>
      </ros>

      <!-- Wheel information -->
      <update_rate>1</update_rate>
      <left_joint>wheel_left_joint</left_joint>
      <right_joint>wheel_right_joint</right_joint>
      <wheel_separation>0.270</wheel_separation>
      <wheel_diameter>0.100</wheel_diameter>

      <!-- Limits (can be adjusted later on)-->
      <max_wheel_torque>20</max_wheel_torque>
      <max_wheel_acceleration>2</max_wheel_acceleration>

      <!-- Output -->
      <odometry_frame>odom</odometry_frame>
      <robot_base_frame>base_footprint</robot_base_frame>
      <publish_odom>true</publish_odom>
      <publish_odom_tf>true</publish_odom_tf>
      <publish_wheel_tf>true</publish_wheel_tf>

    </plugin>
  </gazebo>

  <xacro:include filename="$(find zavaquin_description)/urdf/sensors/camera.xacro"/>
  <xacro:include filename="$(find zavaquin_description)/urdf/sensors/imu.xacro"/>
  <xacro:include filename="$(find zavaquin_description)/urdf/sensors/lidar.xacro"/>
  <xacro:include filename="$(find zavaquin_gazebo)/urdf/include/zavaquin_materials.xacro"/>
</robot>
